2025-04-08 08:04:26 | ERROR | PID:7 | Error in list_queues: HTTPConnectionPool(host='localhost', port=15672): Max retries exceeded with url: /api/queues (Caused by NewConnectionError('<urllib3.connection.HTTPConnection object at 0xffff96d22d70>: Failed to establish a new connection: [Errno 111] Connection refused'))
2025-04-08 08:04:32 | ERROR | PID:7 | Error in list_queues: HTTPConnectionPool(host='localhost', port=15672): Max retries exceeded with url: /api/queues (Caused by NewConnectionError('<urllib3.connection.HTTPConnection object at 0xffff9599c3d0>: Failed to establish a new connection: [Errno 111] Connection refused'))
2025-04-08 08:05:33 | ERROR | PID:7 | Error in list_queues: HTTPConnectionPool(host='localhost', port=15672): Max retries exceeded with url: /api/queues (Caused by NewConnectionError('<urllib3.connection.HTTPConnection object at 0xffff9599c460>: Failed to establish a new connection: [Errno 111] Connection refused'))
